Workbook
Name currentYear_liabilities: #REF!
Name Revenue: Ratios!$B$21
Name depreciation: Ratios!$B$26
Name avg_equity: Ratios!$B$33
Name asset_turnover: Ratios!$B$48
Name avg_receivables: Ratios!$B$35
Name interest_expense: Ratios!$B$23
Name avg_inventory: Ratios!$B$34
Name sharesoutstanding: #REF!
Name currentYear_assets_total: Ratios!$B$11
Name EQ: #REF!
Name CurrentINV: #REF!
Name current_liabilities: Ratios!$B$15
Name TA: #REF!
Name CurrentEquity: #REF!
Name CurrentLiabilities: #REF!
Name currentYear_assets: Ratios!$B$14
Name avg_total_capital: Ratios!$B$38
Name Roa_: #REF!
Name Averageassets: #REF!
Name market_cap: #REF!
Name avgequity: #REF!
Name avgrec: #REF!
Name EB: #REF!
Name current_assets: BS!$C$9
Name startinv: #REF!
Name startYear_assets_total: Ratios!$B$5
Name net_income: Ratios!$B$25
Name StartEquity: #REF!
Name ProfitMargin: #REF!
Name markcap: #REF!
Name tax_rate: Ratios!$B$29
Name Netincome: #REF!
Name crnt: BS!$C$3
Name leverage_ratio: Ratios!$B$63
Name total_liabilities: Ratios!$B$17
Name INT_exp: #REF!
Name assets: #REF!
Name avg_recievables: #REF!
Name cash: Ratios!$B$18
Name total_capital_end: Ratios!$B$37
Name inventory_turnover: Ratios!$B$51
Name long_term_debt: Ratios!$B$16
Name ROA: Ratios!$B$42
Name CurrentAssets: #REF!
Name REV: #REF!
Name Interest: #REF!
Name startYear_equity: Ratios!$B$4
Name avginventory: #REF!
Name profit_margin: Ratios!$B$53
Name StartAssets: #REF!
Name startYear_receivables: Ratios!$B$7
Name shares_outstanding: #REF!
Name taxes: Ratios!$B$24
Name INC_Net: #REF!
Name EBIT: Ratios!$B$22
Name StartRecievables: #REF!
Name startYear_inventory: Ratios!$B$6
Name AssetTurnover: #REF!
Name currentYear_equity: Ratios!$B$10

Sheet BS
A1: Apple Balance Sheet | B1: 2022 | C1: 2023
A3: Assets
A4: Cash | B4: 23646 | C4: 29965
A5: Accounts Receiveable | B5: 28184 | C5: 29508
A6: Inventory | B6: 4946 | C6: 6331
A7: Total Current Assets | B7: 135405 | C7: 143566
A8: Net PPE | B8: 42117 | C8: 43715
A9: Total Assets | B9: 352755 | C9: 352583
A11: Liabilities & Equity
A12: Accounts Payable | B12: 64115 | C12: 62611
A13: Total Current Liabilities | B13: 153982 | C13: 145308
A14: Long-Term Debt | B14: 98959 | C14: 95281
A15: Total Liabilities | B15: 302083 | C15: 290437
A16: Equity | B16: 50672 | C16: 62146
A17: Total Liabilities + Equity | B17: =B15+B16 -> 352755 | C17: =C15+C16 -> 352583

Sheet IS
A1: Apple Income Statement | B1: 2023
A3: Revenue | B3: 383285
A4: COGS | B4: 214137
A5: Gross Profit | B5: =B3-B4 -> 169148
A6: Operating Expenses | B6: 54847
A7: EBIT | B7: =B5-B6 -> 114301
A8: Interest Expense | B8: 3933
A9: Pre-Tax Income | B9: =B7-B8 -> 110368
A10: Taxes | B10: 16741
A11: Net Income | B11: =B9-B10 -> 93627
A12: Depreciation | B12: 11519

Sheet CF
A1: Apple Cash Flow
A3: Operating Cash Flow | B3: 110543
A4: Investing Cash Flow | B4: -3765
A5: Financing Cash Flow | B5: 108488
A6: Net Change in Cash | B6: =B3+B4+B5 -> 215266

Sheet Ratios
A1: Inputs
A3: Start-Year (2022)
A4: startYear_equity | B4: =BS!B16 -> 50672
A5: startYear_assets_total | B5: =BS!B9 -> 352755
A6: startYear_inventory | B6: =BS!B6 -> 4946
A7: startYear_receivables | B7: =BS!B5 -> 28184
A9: Current-Year (2023)
A10: currentYear_equity | B10: =BS!C16 -> 62146
A11: currentYear_assets_total | B11: =BS!C9 -> 352583
A12: currentYear_inventory | B12: =BS!C6 -> 6331
A13: currentYear_receivables | B13: =BS!C5 -> 29508
A14: currentYear_assets | B14: =BS!C7 -> 143566
A15: current_liabilities | B15: =BS!C13 -> 145308
A16: long_term_debt | B16: =BS!C14 -> 95281
A17: total_liabilities | B17: =BS!C15 -> 290437
A18: cash | B18: =BS!C4 -> 29965
A20: Income Statement
A21: Revenue | B21: =IS!B3 -> 383285
A22: EBIT | B22: =IS!B7 -> 114301
A23: interest_expense | B23: =IS!B8 -> 3933
A24: taxes | B24: =IS!B10 -> 16741
A25: net_income | B25: =IS!B11 -> 93627
A26: depreciation | B26: =IS!B12 -> 11519
A28: Assumptions
A29: tax_rate | B29: =B24/IS!B9 -> 0.15168346
A31: Averages
A32: avg_total_assets | B32: =(B5+B11)/2 -> 352669
A33: avg_equity | B33: =(B4+B10)/2 -> 56409
A34: avg_inventory | B34: =(B6+B12)/2 -> 5638.5
A35: avg_receivables | B35: =(B7+B13)/2 -> 28846
A36: total_capital_start | B36: =BS!B14+BS!B16 -> 149631
A37: total_capital_end | B37: =BS!C14+BS!C16 -> 157427
A38: avg_total_capital | B38: =(B36+B37)/2 -> 153529
A40: Profitability
A41: ROA (Start) | B41: =net_income/startYear_assets_total -> 0.26541651
A42: ROA (Avg) | B42: =net_income/avg_total_assets -> 0.26548123
A43: ROE (Start) | B43: =net_income/startYear_equity -> 1.8477068
A44: ROE (Avg) | B44: =net_income/avg_equity -> 1.6597883
A45: ROC | B45: =(EBIT*(1-tax_rate))/avg_total_capital -> 0.63156426
A47: Efficiency
...
